<?xml version="1.0" ?>
<robot name="grinding_machine">
  <!-- Base link -->
  <link name="base"/>
  <link name="ee"/>

  <!-- Prismatic joint -->
  <joint name="prismatic_joint" type="prismatic">
    <parent link="base"/>
    <child link="ee"/>
    <origin xyz="0 0 0.5" rpy="0 0 0"/>
    <axis xyz="0 0 1"/>
    <limit lower="-1.0" upper="1.0" effort="10" velocity="1"/>
  </joint>

  <joint name="fixed_joint" type="fixed">
    <parent link="ee"/>
    <child link="spindle"/>
    <!-- <origin xyz="0 0 0.0" rpy="0.0872665 0 0"/>  -->
    <origin xyz="0 0 0.0" rpy="0.174533 0 0"/> <!-- 10 degrees -->
  </joint>


  <!-- Object attached to the robot, described by an .stl file -->
  <link name="spindle">
    <inertial>
      <mass value="1.0"/>
      <inertia ixx="0.1" ixy="0.0" ixz="0.0" iyy="0.1" iyz="0.0" izz="0.1"/>
    </inertial>
    <visual>
      <geometry>
        <cylinder length="0.02" radius="0.01"/>
      </geometry>
    </visual>
    <!-- <collision>
      <geometry>
        <cylinder length="0.02" radius="0.01"/>
      </geometry>
    </collision> -->
  </link>
  <transmission name="prismatic_joint_trans">
    <type>transmission_interface/SimpleTransmission</type>
    <joint name="prismatic_joint">
      <hardwareInterface>EffortJointInterface</hardwareInterface>
    </joint>
    <actuator name="prismatic_actuator">
      <hardwareInterface>EffortJointInterface</hardwareInterface>
      <mechanicalReduction>1</mechanicalReduction>
    </actuator>
  </transmission>
</robot>